<?xml version="1.0"?>
<robot name="Bazu">
	
	<link name="world"/>

	<link name="base_link">
		<inertial>
			<origin xyz="0.0 0.0 0.0" rpy="0.0 0.0 0.025"/>
			<mass value="5.0"/>
			<inertia ixx="0.0510" ixy="0.0" ixz="0.0" iyy="0.0510" iyz="0.0" izz="0.1"/>
		</inertial>

		<visual>
			<origin xyz="0.0 0.0 0.025" rpy="0.0 0.0 0.0"/>
			<geometry>
				<cylinder radius="0.2" length="0.05"/>
			</geometry>
			<material name="Black">
				<color rgba="0.0 0.0 0.0 1.0"/>
			</material>
		</visual>

		<collision>
			<origin xyz="0.0 0.0 0.025" rpy="0.0 0.0 0.0"/>
			<geometry>
				<cylinder radius="0.2" length="0.05"/>
			</geometry>
		</collision>
	</link>

	<link name="link_1">
		<inertial>
			<origin xyz="0.0 0.0 0.0" rpy="0.0 0.0 0.025"/>
			<mass value="5.0"/>
			<inertia ixx="0.0792" ixy="0.0" ixz="0.0" iyy="0.0792" iyz="0.0" izz="0.025"/>
		</inertial>

		<visual>
			<origin xyz="0.0 0.0 0.0" rpy="0.0 0.0 0.0"/>
			<geometry>
				<cylinder radius="0.1" length="0.4"/>
			</geometry>
			<material name="Red">
				<color rgba="1.0 0.0 0.0 1.0"/>
			</material>
		</visual>

		<collision>
			<origin xyz="0.0 0.0 0" rpy="0.0 0.0 0.0"/>
			<geometry>
				<cylinder radius="0.1" length="0.4"/>
			</geometry>
		</collision>
	</link>

	<link name="link_fixed">
		<inertial>
			<origin xyz="0.0 0.0 0.0" rpy="0.0 0.0 0.025"/>
			<mass value="5.0"/>
			<inertia ixx="0.0253" ixy="0.0" ixz="0.0" iyy="0.0253" iyz="0.0" izz="0.025"/>
		</inertial>

		<visual>
			<origin xyz="0.0 0.0 0.0" rpy="0.0 1.57 0.0"/>
			<geometry>
				<cylinder radius="0.1" length="0.175"/>
			</geometry>
			<material name="Blue">
				<color rgba="0.0 0.0 1.0 1.0"/>
			</material>
		</visual>

		<collision>
			<origin xyz="0.0 0.0 0.0" rpy="0.0 1.57 0.0"/>
			<geometry>
				<cylinder radius="0.1" length="0.175"/>
			</geometry>
		</collision>
	</link>

	<link name="link_2">
		<inertial>
			<origin xyz="0.0 0.0 0.0" rpy="0.0 0.0 0.025"/>
			<mass value="5.0"/>
			<inertia ixx="0.1531" ixy="0.0" ixz="0.0" iyy="0.1531" iyz="0.0" izz="0.00625"/>
		</inertial>

		<visual>
			<origin xyz="0.0 0.0 0.0" rpy="1.57 0.0 0.0"/>
			<geometry>
				<cylinder radius="0.05" length="0.6"/>
			</geometry>
			<material name="Red">
				<color rgba="1.0 0.0 0.0 1.0"/>
			</material>
		</visual>

		<collision>
			<origin xyz="0.0 0.0 0.0" rpy="0.0 1.57 0.0"/>
			<geometry>
				<cylinder radius="0.1" length="0.175"/>
			</geometry>
		</collision>
	</link>

	<link name="link_fixed2">
		<inertial>
			<origin xyz="0.0 0.0 0.0" rpy="0.0 0.0 0.025"/>
			<mass value="5.0"/>
			<inertia ixx="0.0253" ixy="0.0" ixz="0.0" iyy="0.0253" iyz="0.0" izz="0.025"/>
		</inertial>

		<visual>
			<origin xyz="0.0 0.0 0.0" rpy="0.0 1.57 0.0"/>
			<geometry>
				<cylinder radius="0.1" length="0.175"/>
			</geometry>
			<material name="Blue">
				<color rgba="0.0 0.0 1.0 1.0"/>
			</material>
		</visual>

		<collision>
			<origin xyz="0.0 0.0 0.0" rpy="0.0 1.57 0.0"/>
			<geometry>
				<cylinder radius="0.1" length="0.175"/>
			</geometry>
		</collision>
	</link>

	<link name="link_3">
		<inertial>
			<origin xyz="0.0 0.0 0.0" rpy="0.0 0.0 0.025"/>
			<mass value="5.0"/>
			<inertia ixx="0.0406" ixy="0.0" ixz="0.0" iyy="0.0406" iyz="0.0" izz="0.00625"/>
		</inertial>

		<visual>
			<origin xyz="0.0 0.0 0.0" rpy="1.57 0.0 0.0"/>
			<geometry>
				<cylinder radius="0.05" length="0.3"/>
			</geometry>
			<material name="Red">
				<color rgba="1.0 0.0 0.0 1.0"/>
			</material>
		</visual>

		<collision>
			<origin xyz="0.0 0.0 0.0" rpy="0.0 1.57 0.0"/>
			<geometry>
				<cylinder radius="0.1" length="0.175"/>
			</geometry>
		</collision>
	</link>


	<joint name="joint_base" type="fixed">
		<parent link="world"/>
		<child link="base_link"/>
		<origin xyz="0.0 0.0 0.0" rpy="0.0 0.0 0.0"/>
	</joint>

	<joint name="joint_1" type="revolute">
		<parent link="base_link"/>
		<child link="link_1"/>
		<axis xyz="0 0 1"/>
		<limit lower="-3.14159" upper="3.14159" velocity="50.0" effort="1000.0"/>
		<origin xyz="0.0 0.0 0.25" rpy="0.0 0.0 0.0"/>
	</joint>

	<joint name="joint_fixed" type="revolute">
		<parent link="link_1"/>
		<child link="link_fixed"/>
		<axis xyz="1 0 0"/>
		<limit lower="0" upper="3.14159" velocity="50.0" effort="1000.0"/>
		<origin xyz="0.0 0.0 0.27" rpy="0.0 0.0 0.0"/>
	</joint>
	
	<joint name="joint_2" type="fixed">
		<parent link="link_fixed"/>
		<child link="link_2"/>
		<origin xyz="0.0 0.38 0.0" rpy="0.0 0.0 0.0"/>
	</joint>

	<joint name="joint_fixed2" type="revolute">
		<parent link="link_2"/>
		<child link="link_fixed2"/>
		<axis xyz="1 0 0"/>
		<limit lower="-1.57" upper="1.57" velocity="50.0" effort="1000.0"/>
		<origin xyz="0.0 0.3 0.0" rpy="0.0 0.0 0.0"/>
	</joint>

	<joint name="joint_3" type="fixed">
		<parent link="link_fixed2"/>
		<child link="link_3"/>
		<origin xyz="0.0 0.23 0.0" rpy="0.0 0.0 0.0"/>
	</joint>

	<gazebo reference="base_link">
		<material>Gazebo/Black</material>
	</gazebo>

	<gazebo reference="link_1">
		<material>Gazebo/Orange</material>
	</gazebo>

	<gazebo reference="link_2">
		<material>Gazebo/Orange</material>
	</gazebo>

	<gazebo reference="link_3">
		<material>Gazebo/Orange</material>
	</gazebo>

	<gazebo reference="link_fixed">
		<material>Gazebo/Blue</material>
	</gazebo>

	<gazebo reference="link_fixed2">
		<material>Gazebo/Blue</material>
	</gazebo>

	<gazebo>
		<plugin filename="ignition-gazebo-joint-state-publisher-system" name="ignition::gazebo::systems::JointStatePublisher"/>
	</gazebo>

</robot>
