<?xml version="1.0" ?>
<!-- =================================================================================== -->
<!-- |    This document was autogenerated by xacro from ./urdf/iiwa7.urdf.xacro        | -->
<!-- |    EDITING THIS FILE BY HAND IS NOT RECOMMENDED                                 | -->
<!-- =================================================================================== -->
<robot name="iiwa7">
  <link name="world"/>
  <!-- Переменные -->
  <!-- <xacro:property name="mesh_link" value="package://robot_control/meshes/iiwa7/visual"/> -->
  <!-- Материалы -->
  <material name="grey">
    <color rgba="0.5 0.5 0.5 1"/>
  </material>
  <material name="orange">
    <color rgba="1 0.5 0 1"/>
  </material>
  <material name="white">
    <color rgba="1 1 1 1.0"/>
  </material>
  <!-- Ссылки -->
  <link name="link_0">
    <inertial>
      <origin rpy="0 0 0" xyz="-0.1 0 0.07"/>
      <mass value="5"/>
      <inertia ixx="0.035" ixy="0" ixz="0" iyy="0.035" iyz="0" izz="0.012"/>
    </inertial>
    <visual>
      <origin rpy="0.0 0.0 0.0" xyz="0.0 0.0 0.0"/>
      <geometry>
        <mesh filename="file:///home/ros/robotics_control_ros_ws/install/robot_control/share/robot_control/meshes/iiwa7/visual/link_0.stl" scale="1 1 1"/>
      </geometry>
      <material name="grey"/>
    </visual>
    <collision>
      <origin rpy="0.0 0.0 0.0" xyz="0.0 0.0 0.0"/>
      <geometry>
        <mesh filename="file:///home/ros/robotics_control_ros_ws/install/robot_control/share/robot_control/meshes/iiwa7/visual/link_0.stl" scale="1 1 1"/>
      </geometry>
      <material name="grey"/>
    </collision>
  </link>
  <link name="link_1">
    <inertial>
      <origin rpy="0 0 0" xyz="0 -0.03 0.12"/>
      <mass value="3.4525"/>
      <inertia ixx="0.02183" ixy="0" ixz="0" iyy="0.007703" iyz="-0.003887" izz="0.02083"/>
    </inertial>
    <visual>
      <origin rpy="0 0 0" xyz="0.0 0.0 0.0"/>
      <geometry>
        <mesh filename="file:///home/ros/robotics_control_ros_ws/install/robot_control/share/robot_control/meshes/iiwa7/visual/link_1.stl" scale="1 1 1"/>
      </geometry>
      <material name="orange"/>
    </visual>
    <collision>
      <origin rpy="0.0 0.0 0.0" xyz="0.0 0.0 0.0"/>
      <geometry>
        <mesh filename="file:///home/ros/robotics_control_ros_ws/install/robot_control/share/robot_control/meshes/iiwa7/visual/link_1.stl" scale="1 1 1"/>
      </geometry>
      <material name="orange"/>
    </collision>
  </link>
  <link name="link_2">
    <inertial>
      <origin rpy="0 0 0" xyz="0.0003 0.059 0.042"/>
      <mass value="3.4821"/>
      <inertia ixx="0.02076" ixy="0" ixz="-0.003626" iyy="0.02179" iyz="0" izz="0.00779"/>
    </inertial>
    <visual>
      <origin rpy="0 0 0" xyz="0.0 0.0 0.0"/>
      <geometry>
        <mesh filename="file:///home/ros/robotics_control_ros_ws/install/robot_control/share/robot_control/meshes/iiwa7/visual/link_2.stl" scale="1 1 1"/>
      </geometry>
      <material name="orange"/>
    </visual>
    <collision>
      <origin rpy="0.0 0.0 0.0" xyz="0.0 0.0 0.0"/>
      <geometry>
        <mesh filename="file:///home/ros/robotics_control_ros_ws/install/robot_control/share/robot_control/meshes/iiwa7/visual/link_2.stl" scale="1 1 1"/>
      </geometry>
      <material name="orange"/>
    </collision>
  </link>
  <link name="link_3">
    <inertial>
      <origin rpy="0 0 0" xyz="0 0.03 0.13"/>
      <mass value="4.05623"/>
      <inertia ixx="0.03204" ixy="0" ixz="0" iyy="0.00972" iyz="0.006227" izz="0.03042"/>
    </inertial>
    <visual>
      <origin rpy="0 0 0" xyz="0.0 0.0 -0.026"/>
      <geometry>
        <mesh filename="file:///home/ros/robotics_control_ros_ws/install/robot_control/share/robot_control/meshes/iiwa7/visual/link_3.stl" scale="1 1 1"/>
      </geometry>
      <material name="orange"/>
    </visual>
    <collision>
      <origin rpy="0.0 0.0 0.0" xyz="0.0 0.0 -0.026"/>
      <geometry>
        <mesh filename="file:///home/ros/robotics_control_ros_ws/install/robot_control/share/robot_control/meshes/iiwa7/visual/link_3.stl" scale="1 1 1"/>
      </geometry>
      <material name="orange"/>
    </collision>
  </link>
  <link name="link_4">
    <inertial>
      <origin rpy="0 0 0" xyz="0 0.067 0.034"/>
      <mass value="3.4822"/>
      <inertia ixx="0.02178" ixy="0" ixz="0" iyy="0.02075" iyz="-0.003625" izz="0.007785"/>
    </inertial>
    <visual>
      <origin rpy="0 0 0" xyz="0.0 0.0 0"/>
      <geometry>
        <mesh filename="file:///home/ros/robotics_control_ros_ws/install/robot_control/share/robot_control/meshes/iiwa7/visual/link_4.stl" scale="1 1 1"/>
      </geometry>
      <material name="orange"/>
    </visual>
    <collision>
      <origin rpy="0.0 0.0 0.0" xyz="0.0 0.0 0.0"/>
      <geometry>
        <mesh filename="file:///home/ros/robotics_control_ros_ws/install/robot_control/share/robot_control/meshes/iiwa7/visual/link_4.stl" scale="1 1 1"/>
      </geometry>
      <material name="orange"/>
    </collision>
  </link>
  <link name="link_5">
    <inertial>
      <origin rpy="0 0 0" xyz="0.0001 0.021 0.076"/>
      <mass value="2.1633"/>
      <inertia ixx="0.01287" ixy="0" ixz="0" iyy="0.005708" iyz="-0.003946" izz="0.01112"/>
    </inertial>
    <visual>
      <origin rpy="0 0 0" xyz="0.0 0.0 -0.026"/>
      <geometry>
        <mesh filename="file:///home/ros/robotics_control_ros_ws/install/robot_control/share/robot_control/meshes/iiwa7/visual/link_5.stl" scale="1 1 1"/>
      </geometry>
      <material name="orange"/>
    </visual>
    <collision>
      <origin rpy="0.0 0.0 0.0" xyz="0.0 0.0 -0.026"/>
      <geometry>
        <mesh filename="file:///home/ros/robotics_control_ros_ws/install/robot_control/share/robot_control/meshes/iiwa7/visual/link_5.stl" scale="1 1 1"/>
      </geometry>
      <material name="orange"/>
    </collision>
  </link>
  <link name="link_6">
    <!-- Инерция -->
    <inertial>
      <origin rpy="0 0 0" xyz="0 0.0006 0.0004"/>
      <mass value="2.3466"/>
      <inertia ixx="0.006509" ixy="0" ixz="0" iyy="0.006259" iyz="0.00031891" izz="0.004527"/>
    </inertial>
    <!-- Визуализация -->
    <visual>
      <origin rpy="0 0 0" xyz="0.0 0.0 0"/>
      <geometry>
        <mesh filename="file:///home/ros/robotics_control_ros_ws/install/robot_control/share/robot_control/meshes/iiwa7/visual/link_6.stl" scale="1 1 1"/>
      </geometry>
      <material name="orange"/>
    </visual>
    <!-- Коллизия -->
    <collision>
      <origin rpy="0.0 0.0 0.0" xyz="0.0 0.0 0.0"/>
      <geometry>
        <mesh filename="file:///home/ros/robotics_control_ros_ws/install/robot_control/share/robot_control/meshes/iiwa7/visual/link_6.stl" scale="1 1 1"/>
      </geometry>
      <material name="orange"/>
    </collision>
  </link>
  <link name="link_7">
    <!-- Инерция -->
    <inertial>
      <origin rpy="0 0 0" xyz="0 0 0.02"/>
      <mass value="3.129"/>
      <inertia ixx="0.01464" ixy="0.0005912" ixz="0" iyy="0.01465" iyz="0" izz="0.002872"/>
    </inertial>
    <!-- Визуализация -->
    <visual>
      <origin rpy="0 0 0" xyz="0.0 0.0 -0.0005"/>
      <geometry>
        <mesh filename="file:///home/ros/robotics_control_ros_ws/install/robot_control/share/robot_control/meshes/iiwa7/visual/link_7.stl" scale="1 1 1"/>
      </geometry>
      <material name="orange"/>
    </visual>
    <!-- Коллизия -->
    <collision>
      <origin rpy="0.0 0.0 0.0" xyz="0.0 0.0 -0.0005"/>
      <geometry>
        <mesh filename="file:///home/ros/robotics_control_ros_ws/install/robot_control/share/robot_control/meshes/iiwa7/visual/link_7.stl" scale="1 1 1"/>
      </geometry>
      <material name="orange"/>
    </collision>
  </link>
  <link name="link_ee"/>
  <!-- Соединения -->
  <joint name="virtual_joint" type="fixed">
    <!-- <parent link="plate_under_link"/> -->
    <parent link="world"/>
    <child link="link_0"/>
    <origin rpy="0 0.0 0.0" xyz="0.0 0.0 0.0"/>
  </joint>
  <joint name="joint_1" type="revolute">
    <parent link="link_0"/>
    <child link="link_1"/>
    <axis xyz="0 0 1"/>
    <limit effort="300" lower="-2.9670597283903604" upper="2.9670597283903604" velocity="10"/>
    <origin rpy="0 0 0" xyz="0 0 0.15"/>
  </joint>
  <joint name="joint_2" type="revolute">
    <parent link="link_1"/>
    <child link="link_2"/>
    <axis xyz="0 0 1"/>
    <limit effort="300" lower="-2.0943951023931953" upper="2.0943951023931953" velocity="10"/>
    <origin rpy="1.5707963267948966 0 3.141592653589793" xyz="0 0 0.185"/>
  </joint>
  <joint name="joint_3" type="revolute">
    <parent link="link_2"/>
    <child link="link_3"/>
    <axis xyz="0 0 1"/>
    <limit effort="300" lower="-2.9670597283903604" upper="2.9670597283903604" velocity="10"/>
    <origin rpy="1.5707963267948966 0 3.141592653589793" xyz="0 0.21 0"/>
  </joint>
  <joint name="joint_4" type="revolute">
    <parent link="link_3"/>
    <child link="link_4"/>
    <axis xyz="0 0 1"/>
    <limit effort="300" lower="-2.0943951023931953" upper="2.0943951023931953" velocity="10"/>
    <origin rpy="1.5707963267948966 0 0" xyz="0 0 0.19"/>
  </joint>
  <joint name="joint_5" type="revolute">
    <parent link="link_4"/>
    <child link="link_5"/>
    <axis xyz="0 0 1"/>
    <limit effort="300" lower="-2.9670597283903604" upper="2.9670597283903604" velocity="10"/>
    <origin rpy="-1.5707963267948966 3.141592653589793 0" xyz="0 0.21 0"/>
  </joint>
  <joint name="joint_6" type="revolute">
    <parent link="link_5"/>
    <child link="link_6"/>
    <axis xyz="0 0 1"/>
    <limit effort="300" lower="-2.0943951023931953" upper="2.0943951023931953" velocity="10"/>
    <origin rpy="1.5707963267948966 0 0" xyz="0 0.06070 0.19"/>
  </joint>
  <joint name="joint_7" type="revolute">
    <parent link="link_6"/>
    <child link="link_7"/>
    <axis xyz="0 0 1"/>
    <limit effort="300" lower="-3.0543261909900763" upper="3.0543261909900763" velocity="10"/>
    <origin rpy="-1.5707963267948966 3.141592653589793 0" xyz="0 0.081 0.06070"/>
  </joint>
  <joint name="iiwa_joint_ee" type="fixed">
    <parent link="link_7"/>
    <child link="link_ee"/>
    <origin rpy="0 1.5707963267948966 0" xyz="0 0 0.045"/>
  </joint>
  <transmission name="$tran_1">
    <plugin>transmission_interface/SimpleTransmission</plugin>
    <joint name="$joint_1" role="joint1">
      <mechanical_reduction>1</mechanical_reduction>
    </joint>
    <actuator name="$motor_1" role="actuator1"/>
  </transmission>
  <transmission name="$tran_2">
    <plugin>transmission_interface/SimpleTransmission</plugin>
    <joint name="$joint_2" role="joint1">
      <mechanical_reduction>1</mechanical_reduction>
    </joint>
    <actuator name="$motor_2" role="actuator1"/>
  </transmission>
  <transmission name="$tran_3">
    <plugin>transmission_interface/SimpleTransmission</plugin>
    <joint name="$joint_3" role="joint1">
      <mechanical_reduction>1</mechanical_reduction>
    </joint>
    <actuator name="$motor_3" role="actuator1"/>
  </transmission>
  <transmission name="$tran_4">
    <plugin>transmission_interface/SimpleTransmission</plugin>
    <joint name="$joint_4" role="joint1">
      <mechanical_reduction>1</mechanical_reduction>
    </joint>
    <actuator name="$motor_4" role="actuator1"/>
  </transmission>
  <transmission name="$tran_5">
    <plugin>transmission_interface/SimpleTransmission</plugin>
    <joint name="$joint_5" role="joint1">
      <mechanical_reduction>1</mechanical_reduction>
    </joint>
    <actuator name="$motor_5" role="actuator1"/>
  </transmission>
  <transmission name="$tran_6">
    <plugin>transmission_interface/SimpleTransmission</plugin>
    <joint name="$joint_6" role="joint1">
      <mechanical_reduction>1</mechanical_reduction>
    </joint>
    <actuator name="$motor_6" role="actuator1"/>
  </transmission>
  <transmission name="$tran_7">
    <plugin>transmission_interface/SimpleTransmission</plugin>
    <joint name="$joint_7" role="joint1">
      <mechanical_reduction>1</mechanical_reduction>
    </joint>
    <actuator name="$motor_7" role="actuator1"/>
  </transmission>
  <!-- Кастомный контроллер -->
  <!-- <ros2_control name="CustomController" type="system">
        <hardware>
            <plugin>robot_controller/CustomController</plugin>
            <param name="example_param_hw_start_duration_sec">0</param>
            <param name="example_param_hw_stop_duration_sec">3.0</param>
            <param name="example_param_hw_slowdown">100</param>
        </hardware>

        <joint name="joint_1">
            <command_interface name="position">
              <param name="min">-${170 * pi / 180}</param>
              <param name="max">${170 * pi / 180}</param>
            </command_interface>
  
            <state_interface name="position"/>
        </joint>
    </ros2_control> -->
  <!-- Для Gazebo Ignition и выше -->
  <ros2_control name="GazeboSimSystem" type="system">
    <hardware>
      <plugin>gz_ros2_control/GazeboSimSystem</plugin>
    </hardware>
    <joint name="joint_1">
      <command_interface name="position">
        <param name="min">-2.9670597283903604</param>
        <param name="max">2.9670597283903604</param>
      </command_interface>
      <state_interface name="position">
        <param name="initial_value">0</param>
      </state_interface>
      <state_interface name="acceleration"/>
      <state_interface name="velocity"/>
      <state_interface name="effort"/>
    </joint>
    <joint name="joint_2">
      <command_interface name="position">
        <param name="min">-2.0943951023931953</param>
        <param name="max">2.0943951023931953</param>
      </command_interface>
      <state_interface name="position">
        <param name="initial_value">0</param>
      </state_interface>
      <state_interface name="acceleration"/>
      <state_interface name="velocity"/>
      <state_interface name="effort"/>
    </joint>
    <joint name="joint_3">
      <command_interface name="position">
        <param name="min">-2.9670597283903604</param>
        <param name="max">2.9670597283903604</param>
      </command_interface>
      <state_interface name="position">
        <param name="initial_value">0</param>
      </state_interface>
      <state_interface name="acceleration"/>
      <state_interface name="velocity"/>
      <state_interface name="effort"/>
    </joint>
    <joint name="joint_4">
      <command_interface name="position">
        <param name="min">-2.0943951023931953</param>
        <param name="max">2.0943951023931953</param>
      </command_interface>
      <state_interface name="position">
        <param name="initial_value">0</param>
      </state_interface>
      <state_interface name="acceleration"/>
      <state_interface name="velocity"/>
      <state_interface name="effort"/>
    </joint>
    <joint name="joint_5">
      <command_interface name="position">
        <param name="min">-2.9670597283903604</param>
        <param name="max">2.9670597283903604</param>
      </command_interface>
      <state_interface name="position">
        <param name="initial_value">0</param>
      </state_interface>
      <state_interface name="acceleration"/>
      <state_interface name="velocity"/>
      <state_interface name="effort"/>
    </joint>
    <joint name="joint_6">
      <command_interface name="position">
        <param name="min">-2.0943951023931953</param>
        <param name="max">2.0943951023931953</param>
      </command_interface>
      <state_interface name="position">
        <param name="initial_value">0</param>
      </state_interface>
      <state_interface name="acceleration"/>
      <state_interface name="velocity"/>
      <state_interface name="effort"/>
    </joint>
    <joint name="joint_7">
      <command_interface name="position">
        <param name="min">-3.0543261909900763</param>
        <param name="max">3.0543261909900763</param>
      </command_interface>
      <state_interface name="position">
        <param name="initial_value">0</param>
      </state_interface>
      <state_interface name="acceleration"/>
      <state_interface name="velocity"/>
      <state_interface name="effort"/>
    </joint>
  </ros2_control>
  <!-- Для Gazebo Classic -->
  <!-- <ros2_control name="RobotSystem" type="system">
        <hardware>
            <plugin>gazebo_ros2_control/GazeboSystem</plugin>
        </hardware>

        <joint name="joint_1">
            <command_interface name="position">
                <param name="min">-${170 * pi / 180}</param>
                <param name="max">${170 * pi / 180}</param>
            </command_interface>
            <state_interface name="position"/>
        </joint>

        <joint name="joint_2">
            <command_interface name="position">
                <param name="min">-${120 * pi / 180}</param>
                <param name="max">${120 * pi / 180}</param>
            </command_interface>
            <state_interface name="position"/>
        </joint>

        <joint name="joint_3">
            <command_interface name="position">
                <param name="min">-${170 * pi / 180}</param>
                <param name="max">${170 * pi / 180}</param>
            </command_interface>
            <state_interface name="position"/>
        </joint>

        <joint name="joint_4">
            <command_interface name="position">
                <param name="min">-${120 * pi / 180}</param>
                <param name="max">${120 * pi / 180}</param>
            </command_interface>
            <state_interface name="position"/>
        </joint>

        <joint name="joint_5">
            <command_interface name="position">
                <param name="min">-${170 * pi / 180}</param>
                <param name="max">${170 * pi / 180}</param>
            </command_interface>
            <state_interface name="position"/>
        </joint>

        <joint name="joint_6">
            <command_interface name="position">
                <param name="min">-${120 * pi / 180}</param>
                <param name="max">${120 * pi / 180}</param>
            </command_interface>
            <state_interface name="position"/>
        </joint>

        <joint name="joint_7">
            <command_interface name="position">
                <param name="min">-${175 * pi / 180}</param>
                <param name="max">${175 * pi / 180}</param>
            </command_interface>
            <state_interface name="position"/>
        </joint>
    </ros2_control> -->
  <!-- Gazebo настройки -->
  <!-- Газебо плагины для clasic-->
  <!-- <gazebo>
        <plugin name="gazebo_ros2_control" filename="libgazebo_ros2_control.so">
          <robot_param>robot_description</robot_param>
          <robot_param_node>robot_state_publisher</robot_param_node>
          <parameters>$(find iiwa_controller)/config/iiwa_contollers.yaml</parameters>
        </plugin>
    </gazebo> -->
  <!-- Газебо плагины для ignition и выше-->
  <gazebo>
    <plugin filename="gz_ros2_control-system" name="gz_ros2_control::GazeboSimROS2ControlPlugin">
      <robot_param>robot_description</robot_param>
      <robot_param_node>robot_state_publisher</robot_param_node>
      <!-- <parameters>$(find robot_control)/config/robot_contoller.yaml</parameters> -->
      <parameters>/home/ros/robotics_control_ros_ws/install/robot_control/share/robot_control/config/robot_controller.yaml</parameters>
    </plugin>
  </gazebo>
  <gazebo reference="link_0">
    <sensor name="sensor_contact" type="contact">
      <contact>
        <collision>link_0_collision</collision>
        <topic>/iiwa7/sensors/contacts/link_0</topic>
      </contact>
    </sensor>
  </gazebo>
  <gazebo reference="link_1">
    <sensor name="sensor_contact_link_1" type="contact">
      <contact>
        <collision>link_1_collision</collision>
        <topic>/iiwa7/sensors/contacts/link_1</topic>
      </contact>
    </sensor>
  </gazebo>
  <gazebo reference="link_2">
    <sensor name="sensor_contact_link_2" type="contact">
      <contact>
        <collision>link_2_collision</collision>
        <topic>/iiwa7/sensors/contacts/link_2</topic>
      </contact>
    </sensor>
  </gazebo>
  <gazebo reference="link_3">
    <sensor name="sensor_contact_link_3" type="contact">
      <contact>
        <collision>link_3_collision</collision>
        <topic>/iiwa7/sensors/contacts/link_3</topic>
      </contact>
    </sensor>
  </gazebo>
  <gazebo reference="link_4">
    <sensor name="sensor_contact_link_4" type="contact">
      <contact>
        <collision>link_4_collision</collision>
        <topic>/iiwa7/sensors/contacts/link_4</topic>
      </contact>
    </sensor>
  </gazebo>
  <gazebo reference="link_5">
    <sensor name="sensor_contact_link_5" type="contact">
      <contact>
        <collision>link_5_collision</collision>
        <topic>/iiwa7/sensors/contacts/link_5</topic>
      </contact>
    </sensor>
  </gazebo>
  <gazebo reference="link_6">
    <sensor name="sensor_contact_link_6" type="contact">
      <contact>
        <collision>link_6_collision</collision>
        <topic>/iiwa7/sensors/contacts/link_6</topic>
      </contact>
    </sensor>
  </gazebo>
  <gazebo reference="link_7">
    <sensor name="sensor_contact_link_7" type="contact">
      <contact>
        <collision>link_7_collision</collision>
        <topic>/iiwa7/sensors/contacts/link_7</topic>
      </contact>
    </sensor>
  </gazebo>
  <!-- Контактный сенсор -->
  <gazebo reference="link_0">
    <sensor name="iiwa_imu" type="imu">
      <always_on>true</always_on>
      <update_rate>200</update_rate>
      <topic>/iiwa7/sensors/imu/link_0</topic>
    </sensor>
  </gazebo>
  <gazebo reference="link_1">
    <sensor name="iiwa_imu_link_1" type="imu">
      <always_on>true</always_on>
      <update_rate>200</update_rate>
      <topic>/iiwa7/sensors/imu/link_1</topic>
    </sensor>
  </gazebo>
  <gazebo reference="link_2">
    <sensor name="iiwa_imu_link_2" type="imu">
      <always_on>true</always_on>
      <update_rate>200</update_rate>
      <topic>/iiwa7/sensors/imu/link_2</topic>
    </sensor>
  </gazebo>
  <gazebo reference="link_3">
    <sensor name="iiwa_imu_link_3" type="imu">
      <always_on>true</always_on>
      <update_rate>200</update_rate>
      <topic>/iiwa7/sensors/imu/link_3</topic>
    </sensor>
  </gazebo>
  <gazebo reference="link_4">
    <sensor name="iiwa_imu_link_4" type="imu">
      <always_on>true</always_on>
      <update_rate>200</update_rate>
      <topic>/iiwa7/sensors/imu/link_4</topic>
    </sensor>
  </gazebo>
  <gazebo reference="link_5">
    <sensor name="iiwa_imu_link_5" type="imu">
      <always_on>true</always_on>
      <update_rate>200</update_rate>
      <topic>/iiwa7/sensors/imu/link_5</topic>
    </sensor>
  </gazebo>
  <gazebo reference="link_6">
    <sensor name="iiwa_imu_link_6" type="imu">
      <always_on>true</always_on>
      <update_rate>200</update_rate>
      <topic>/iiwa7/sensors/imu/link_6</topic>
    </sensor>
  </gazebo>
  <gazebo reference="link_7">
    <sensor name="iiwa_imu_link_7" type="imu">
      <always_on>true</always_on>
      <update_rate>200</update_rate>
      <topic>/iiwa7/sensors/imu/link_7</topic>
    </sensor>
  </gazebo>
  <!-- Цвета материалов -->
  <gazebo reference="link_0">
    <material>Gazebo/Grey</material>
  </gazebo>
  <gazebo reference="link_1">
    <material>Gazebo/Orange</material>
    <mu1>0.2</mu1>
    <mu2>0.2</mu2>
  </gazebo>
  <gazebo reference="link_2">
    <material>Gazebo/Orange</material>
    <mu1>0.2</mu1>
    <mu2>0.2</mu2>
  </gazebo>
  <gazebo reference="link_3">
    <material>Gazebo/Orange</material>
    <mu1>0.2</mu1>
    <mu2>0.2</mu2>
  </gazebo>
  <gazebo reference="link_4">
    <material>Gazebo/Orange</material>
    <mu1>0.2</mu1>
    <mu2>0.2</mu2>
  </gazebo>
  <gazebo reference="link_5">
    <material>Gazebo/Orange</material>
    <mu1>0.2</mu1>
    <mu2>0.2</mu2>
  </gazebo>
  <gazebo reference="link_6">
    <material>Gazebo/Orange</material>
    <mu1>0.2</mu1>
    <mu2>0.2</mu2>
  </gazebo>
  <gazebo reference="link_7">
    <material>Gazebo/Orange</material>
    <mu1>0.2</mu1>
    <mu2>0.2</mu2>
  </gazebo>
</robot>
